<robot name="model_o">

  <link name="hand_base"/>

  <link name="hand_coupler">
    <inertial>
      <origin xyz="0.000000 0.000000 0.025400"/>
      <mass value="10.0"/>
      <inertia ixx="1000.0" ixy="0.0" ixz="0.0" iyy="1000.0" iyz="0.0" izz="1000.0"/>
    </inertial>
    <visual>
      <material name="lightlue">
        <color rgba="0. 0.3 1.0 1.0"/>
      </material>
      <origin rpy="0 1.57079632679 0" xyz="0.000000 0.000000 0.000000"/>
      <geometry>
        <box size = "0.098 0.113 0.00762"/>
      </geometry>
    </visual>
    <collision>
      <origin rpy="0 1.57079632679 0" xyz="0.000000 0.000000 0.000000"/>
      <geometry>
        <box size = "0.098 0.113 0.00762"/>
      </geometry>
    </collision>
  </link>

  <link name="motor_space">
    <inertial>
      <origin xyz="0.000000 0.000000 0.025400"/>
      <mass value="10.0"/>
      <inertia ixx="1000.0" ixy="0.0" ixz="0.0" iyy="1000.0" iyz="0.0" izz="1000.0"/>
    </inertial>
    <visual>
      <material name="black">
        <color rgba="0. 0. 0. 1.0"/>
      </material>
      <origin rpy="0 1.57079632679 0" xyz="0.000000 0.000000 0.000000"/>
      <geometry>
        <box size = "0.098 0.113 0.06"/>
      </geometry>
    </visual>
    <collision>
      <origin rpy="0 1.57079632679 0" xyz="0.000000 0.000000 0.000000"/>
      <geometry>
        <box size = "0.098 0.113 0.06"/>
      </geometry>
    </collision>
  </link>

  <link name="simple_base">
    <inertial>
      <origin xyz="0.000000 0.000000 0.025400"/>
      <mass value="10.0"/>
      <inertia ixx="1000.0" ixy="0.0" ixz="0.0" iyy="1000.0" iyz="0.0" izz="1000.0"/>
    </inertial>
    <visual>
      <material name="lightlue">
        <color rgba="0. 0.3 1.0 1.0"/>
      </material>
      <origin rpy="0 1.57079632679 0" xyz="0.000000 0.000000 0.000000"/>
      <geometry>
        <box size = "0.098 0.128 0.003"/>
      </geometry>
    </visual>
    <collision>
      <origin rpy="0 1.57079632679 0" xyz="0.000000 0.000000 0.000000"/>
      <geometry>
        <box size = "0.098 0.128 0.003"/>
      </geometry>
    </collision>
  </link>

  <link name="prox_t">
    <inertial>
      <origin xyz="-0.015875 -0.009000 -0.071550" />
      <mass value="1.0" />
      <inertia ixx="1.0" ixy="0.0" ixz="0.0" iyy="1.0" iyz="0.0" izz="1.0" />
    </inertial>
    <visual>
      <material name="white">
        <color rgba="1.0 1.0 1.0 1.0" />
      </material>
      <origin rpy="0 -3.141592 2.4" xyz="-0.00 0.0753 0.008" />
      <geometry>
        <mesh filename="package://wam_t42/models/model_o/proximal.STL" scale="0.00100 0.00100 0.00100" />
      </geometry>
    </visual>
    <collision>
      <origin rpy="1.5707 0 0" xyz="0.00 0.032 0.00" />
      <geometry>
        <box size="0.02400 0.018 0.08340" />
      </geometry>
    </collision>
  </link>

  <link name="distal_t">
    <inertial>
      <origin xyz="-0.015875 -0.009000 -0.071550" />
      <mass value="1.0" />
      <inertia ixx="1.0" ixy="0.0" ixz="0.0" iyy="1.0" iyz="0.0" izz="1.0" />
    </inertial>
    <visual>
      <material name="white">
        <color rgba="1.0 1.0 1.0 1.0" />
      </material>
      <origin rpy="0 0 -2.4962" xyz="-0.0179 0.0459 -0.008" />
      <geometry>
        <mesh filename="package://wam_t42/models/model_o/distal.STL" scale="0.00100 0.00100 0.00100" />
      </geometry>
    </visual>
    <collision>
      <origin rpy="0 0 -2.4962" xyz="-0.0179 0.0459 -0.008" />
      <geometry>
        <mesh filename="package://wam_t42/models/model_o/distal.STL" scale="0.00100 0.00100 0.00100" />
      </geometry>
    </collision>
  </link>

  <link name="prox_rotate_l">
    <inertial>
      <origin xyz="-0.015875 -0.009000 -0.071550" />
      <mass value="1.0" />
      <inertia ixx="1.0" ixy="0.0" ixz="0.0" iyy="1.0" iyz="0.0" izz="1.0" />
    </inertial>
    <visual>
      <material name="white">
        <color rgba="1.0 1.0 1.0 1.0" />
      </material>
      <origin rpy="0 1.57 0" xyz="-0.00 0.0 0.00" />
      <geometry>
        <cylinder length="0.002" radius="0.018" />
      </geometry>
    </visual>
    <collision>
      <origin rpy="0 1.57 0 " xyz="0.00 0.0 0.00" />
      <geometry>
        <cylinder length="0.002" radius="0.018" />
      </geometry>
    </collision>
  </link>

  <link name="prox_l">
    <inertial>
      <origin xyz="-0.015875 -0.009000 -0.071550" />
      <mass value="1.0" />
      <inertia ixx="1.0" ixy="0.0" ixz="0.0" iyy="1.0" iyz="0.0" izz="1.0" />
    </inertial>
    <visual>
      <material name="white">
        <color rgba="1.0 1.0 1.0 1.0" />
      </material>
      <origin rpy="0 -3.141592 2.4" xyz="-0.00 0.0753 0.008" />
      <geometry>
        <mesh filename="package://wam_t42/models/model_o/proximal.STL" scale="0.00100 0.00100 0.00100" />
      </geometry>
    </visual>
    <collision>
      <origin rpy="1.5707 0 0" xyz="0.00 0.032 0.00" />
      <geometry>
        <box size="0.02400 0.018 0.08340" />
      </geometry>
    </collision>
  </link>

  <link name="distal_l">
    <inertial>
      <origin xyz="-0.015875 -0.009000 -0.071550" />
      <mass value="1.0" />
      <inertia ixx="1.0" ixy="0.0" ixz="0.0" iyy="1.0" iyz="0.0" izz="1.0" />
    </inertial>
    <visual>
      <material name="white">
        <color rgba="1.0 1.0 1.0 1.0" />
      </material>
      <origin rpy="0 0 -2.4962" xyz="-0.0179 0.0459 -0.008" />
      <geometry>
        <mesh filename="package://wam_t42/models/model_o/distal.STL" scale="0.00100 0.00100 0.00100" />
      </geometry>
    </visual>
    <collision>
      <origin rpy="0 0 -2.4962" xyz="-0.0179 0.0459 -0.008" />
      <geometry>
        <mesh filename="package://wam_t42/models/model_o/distal.STL" scale="0.00100 0.00100 0.00100" />
      </geometry>
    </collision>
  </link>

  <link name="prox_rotate_r">
    <inertial>
      <origin xyz="-0.015875 -0.009000 -0.071550" />
      <mass value="1.0" />
      <inertia ixx="1.0" ixy="0.0" ixz="0.0" iyy="1.0" iyz="0.0" izz="1.0" />
    </inertial>
    <visual>
      <material name="white">
        <color rgba="1.0 1.0 1.0 1.0" />
      </material>
      <origin rpy="0 1.57 0" xyz="-0.00 0.0 0.00" />
      <geometry>
        <cylinder length="0.002" radius="0.018" />
      </geometry>
    </visual>
    <collision>
      <origin rpy="0 1.57 0 " xyz="0.00 0.0 0.00" />
      <geometry>
        <cylinder length="0.002" radius="0.018" />
      </geometry>
    </collision>
  </link>

  <link name="prox_r">
    <inertial>
      <origin xyz="-0.015875 -0.009000 -0.071550" />
      <mass value="1.0" />
      <inertia ixx="1.0" ixy="0.0" ixz="0.0" iyy="1.0" iyz="0.0" izz="1.0" />
    </inertial>
    <visual>
      <material name="white">
        <color rgba="1.0 1.0 1.0 1.0" />
      </material>
      <origin rpy="0 -3.141592 2.4" xyz="-0.00 0.0753 0.008" />
      <geometry>
        <mesh filename="package://wam_t42/models/model_o/proximal.STL" scale="0.00100 0.00100 0.00100" />
      </geometry>
    </visual>
    <collision>
      <origin rpy="1.5707 0 0" xyz="0.00 0.032 0.00" />
      <geometry>
        <box size="0.02400 0.018 0.08340" />
      </geometry>
    </collision>
  </link>



  <link name="distal_r">
    <inertial>
      <origin xyz="-0.015875 -0.009000 -0.071550" />
      <mass value="1.0" />
      <inertia ixx="1.0" ixy="0.0" ixz="0.0" iyy="1.0" iyz="0.0" izz="1.0" />
    </inertial>
    <visual>
      <material name="white">
        <color rgba="1.0 1.0 1.0 1.0" />
      </material>
      <origin rpy="0 0 -2.4962" xyz="-0.0179 0.0459 -0.008" />
      <geometry>
        <mesh filename="package://wam_t42/models/model_o/distal.STL" scale="0.00100 0.00100 0.00100" />
      </geometry>
    </visual>
    <collision>
      <origin rpy="0 0 -2.4962" xyz="-0.0179 0.0459 -0.008" />
      <geometry>
        <mesh filename="package://wam_t42/models/model_o/distal.STL" scale="0.00100 0.00100 0.00100" />
      </geometry>
    </collision>
  </link>


  <joint name="fixed1" type="fixed">
    <origin rpy="0 0 0" xyz="-0.000381 0.0000 0.000000"/>
    <parent link="hand_base"/>
    <child link="hand_coupler"/>
  </joint>

  <joint name="fixed2" type="fixed">
    <origin rpy="0 0 0" xyz="-0.03381 0.000000 0.000000"/>
    <parent link="hand_coupler"/>
    <child link="motor_space"/>
  </joint>

  <joint name="fixed3" type="fixed">
    <origin rpy="0 0 0" xyz="-0.0315 -0.0075 0.000000"/>
    <parent link="motor_space"/>
    <child link="simple_base"/>
  </joint>

  <joint name="base_to_prox_t" type="revolute">
    <origin rpy="0 0 0" xyz="-0.023 0.034 0.000000" />
    <parent link="simple_base" />
    <child link="prox_t" />
    <limit effort="10000" lower="0.0" upper="3.0" velocity="200" />
    <axis xyz="0 0 1" />
    <dynamics damping="160" friction="0.0" />
  </joint>

  <joint name="prox_to_distal_t" type="revolute">
    <origin rpy="0 0 0" xyz="0.000800 0.062 0" />
    <parent link="prox_t" />
    <child link="distal_t" />
    <limit effort="10000" lower="0.0" upper="1.24" velocity="200" />
    <axis xyz="0 0 1" />
    <dynamics damping="300" friction="0.0" />
 </joint>

 <joint name="base_to_rot_l" type="revolute">
   <origin rpy="4.7123899 0 0" xyz="-0.003 -0.034 -0.027" />
   <parent link="simple_base" />
   <child link="prox_rotate_l" />
   <limit effort="10000" lower="-1.570" upper="0" velocity="200" />
   <axis xyz="1 0 0" />
   <dynamics damping="160" friction="0.0" />
 </joint>

 <joint name="rot_to_prox_l" type="revolute">
   <origin rpy="0 0 0" xyz="-0.02 0 0" />
   <parent link="prox_rotate_l" />
   <child link="prox_l" />
   <limit effort="10000" lower="0.0" upper="3.0" velocity="200" />
   <axis xyz="0 0 1" />
   <dynamics damping="160" friction="0.0" />
 </joint>

 <joint name="prox_to_distal_l" type="revolute">
   <origin rpy="0 0 0" xyz="0.000800 0.062 0" />
   <parent link="prox_l" />
   <child link="distal_l" />
   <limit effort="10000" lower="0.0" upper="1.24" velocity="200" />
   <axis xyz="0 0 1" />
   <dynamics damping="300" friction="0.0" />
</joint>

<joint name="base_to_rot_r" type="revolute">
  <origin rpy="1.5708 0 0" xyz="-0.003 -0.034 0.027" />
  <parent link="simple_base" />
  <child link="prox_rotate_r" />
  <limit effort="10000" lower="0" upper="1.57" velocity="200" />
  <axis xyz="1 0 0" />
  <dynamics damping="160" friction="0.0" />
</joint>

<joint name="rot_to_prox_r" type="revolute">
  <origin rpy="0 0 0" xyz="-0.02 0 0" />
  <parent link="prox_rotate_r" />
  <child link="prox_r" />
  <limit effort="10000" lower="0.0" upper="3.0" velocity="200" />
  <axis xyz="0 0 1" />
  <dynamics damping="160" friction="0.0" />
</joint>


<joint name="prox_to_distal_r" type="revolute">
  <origin rpy="0 0 0" xyz="0.000800 0.062 0" />
  <parent link="prox_r" />
  <child link="distal_r" />
  <limit effort="10000" lower="0.0" upper="1.24" velocity="200" />
  <axis xyz="0 0 1" />
  <dynamics damping="300" friction="0.0" />
</joint>

<gazebo reference="hand_coupler">
  <material>Gazebo/SkyBlue</material>
  <selfCollide>false</selfCollide>
</gazebo>

<gazebo reference="motor_space">
  <material>Gazebo/Black</material>
  <selfCollide>false</selfCollide>
</gazebo>

<gazebo reference="simple_base">
  <material>Gazebo/SkyBlue</material>
  <selfCollide>false</selfCollide>
</gazebo>

<gazebo reference="prox_rotate_l">
  <material>Gazebo/White</material>
  <selfCollide>false</selfCollide>
</gazebo>

<gazebo reference="prox_rotate_r">
  <material>Gazebo/White</material>
  <selfCollide>false</selfCollide>
</gazebo>

<gazebo reference="prox_r">
  <material>Gazebo/White</material>
  <selfCollide>false</selfCollide>
</gazebo>

<gazebo reference="prox_l">
  <material>Gazebo/White</material>
  <selfCollide>false</selfCollide>
</gazebo>

<gazebo reference="prox_t">
  <material>Gazebo/White</material>
  <selfCollide>false</selfCollide>
</gazebo>

<gazebo reference="distal_r">
  <material>Gazebo/Green</material>
  <selfCollide>false</selfCollide>
  <mu1>100000000</mu1>
  <mu2>100000000</mu2>
</gazebo>

<gazebo reference="distal_l">
  <material>Gazebo/Orange</material>
  <selfCollide>false</selfCollide>
  <mu1>100000000</mu1>
  <mu2>100000000</mu2>
</gazebo>

<gazebo reference="distal_t">
  <material>Gazebo/Orange</material>
  <selfCollide>false</selfCollide>
  <mu1>100000000</mu1>
  <mu2>100000000</mu2>
</gazebo>

<transmission name="tran11">
  <type>transmission_interface/SimpleTransmission</type>
  <joint name="base_to_prox_t">
    <hardwareInterface>hardware_interface/PositionJointInterface</hardwareInterface>
  </joint>
  <actuator name="motor11">
    <hardwareInterface>hardware_interface/PositionJointInterface</hardwareInterface>
    <mechanicalReduction>1</mechanicalReduction>
  </actuator>
</transmission>

<transmission name="tran12">
  <type>transmission_interface/SimpleTransmission</type>
  <joint name="prox_to_distal_t">
    <hardwareInterface>hardware_interface/PositionJointInterface</hardwareInterface>
  </joint>
  <actuator name="motor12">
    <hardwareInterface>hardware_interface/PositionJointInterface</hardwareInterface>
    <mechanicalReduction>1</mechanicalReduction>
  </actuator>
</transmission>

<transmission name="tran13">
  <type>transmission_interface/SimpleTransmission</type>
  <joint name="rot_to_prox_r">
    <hardwareInterface>hardware_interface/PositionJointInterface</hardwareInterface>
  </joint>
  <actuator name="motor13">
    <hardwareInterface>hardware_interface/PositionJointInterface</hardwareInterface>
    <mechanicalReduction>1</mechanicalReduction>
  </actuator>
</transmission>

<transmission name="tran14">
  <type>transmission_interface/SimpleTransmission</type>
  <joint name="prox_to_distal_r">
    <hardwareInterface>hardware_interface/PositionJointInterface</hardwareInterface>
  </joint>
  <actuator name="motor14">
    <hardwareInterface>hardware_interface/PositionJointInterface</hardwareInterface>
    <mechanicalReduction>1</mechanicalReduction>
  </actuator>
</transmission>

<transmission name="tran15">
  <type>transmission_interface/SimpleTransmission</type>
  <joint name="rot_to_prox_l">
    <hardwareInterface>hardware_interface/PositionJointInterface</hardwareInterface>
  </joint>
  <actuator name="motor15">
    <hardwareInterface>hardware_interface/PositionJointInterface</hardwareInterface>
    <mechanicalReduction>1</mechanicalReduction>
  </actuator>
</transmission>

<transmission name="tran15">
  <type>transmission_interface/SimpleTransmission</type>
  <joint name="prox_to_distal_l">
    <hardwareInterface>hardware_interface/PositionJointInterface</hardwareInterface>
  </joint>
  <actuator name="motor15">
    <hardwareInterface>hardware_interface/PositionJointInterface</hardwareInterface>
    <mechanicalReduction>1</mechanicalReduction>
  </actuator>
</transmission>

<transmission name="tran16">
  <type>transmission_interface/SimpleTransmission</type>
  <joint name="base_to_rot_r">
    <hardwareInterface>hardware_interface/PositionJointInterface</hardwareInterface>
  </joint>
  <actuator name="motor16">
    <hardwareInterface>hardware_interface/PositionJointInterface</hardwareInterface>
    <mechanicalReduction>1</mechanicalReduction>
  </actuator>
</transmission>

<transmission name="tran17">
  <type>transmission_interface/SimpleTransmission</type>
  <joint name="base_to_rot_l">
    <hardwareInterface>hardware_interface/PositionJointInterface</hardwareInterface>
  </joint>
  <actuator name="motor17">
    <hardwareInterface>hardware_interface/PositionJointInterface</hardwareInterface>
    <mechanicalReduction>1</mechanicalReduction>
  </actuator>
</transmission>

</robot>
